<?xml version="1.0" ?>

<robot name="painter">
	<link name = "base_link">
		<visual>
      			<origin rpy="0 0 0" xyz="0 0 0" />
      			<geometry>
        			<box size="0.1 0.1 0.01" />
      			</geometry>
    		</visual>
	</link>

	<link name="link_01">
    		<visual>
        		<origin rpy="0 0 0" xyz="0 0.1783 0.01" />
        		<geometry>
        		<box size="0.02 0.3566 0.02" />
        		</geometry>
    		</visual>
	</link>

	<link name="link_02">
    		<visual>
        		<origin rpy="0 0 0" xyz="0 0.1448 0" />
        		<geometry>
        		<box size="0.02 0.2896 0.02" />
        		</geometry>
    		</visual>
	</link>

	<link name="tool">
    		<visual>
        		<origin rpy="0 0 0" xyz="0 0 0" />
        		<geometry>
        		<box size="0.01 0.01 0.1" />
        		</geometry>
    		</visual>
	</link>

	<joint name="base_link_link_01" type="revolute">
		<axis xyz="0 0 -1"/>
		<limit effort="1000.0" lower="-3.14" upper="3.14" velocity="0.5"/>
		<origin rpy="0 0 0" xyz="0 0 0.005"/>
		<parent link="base_link"/>
		<child link="link_01"/>
	</joint>

	<joint name="link_01_link_02" type="revolute">
		<axis xyz="0 0 -1"/>
    <limit effort="1000.0" lower="0" upper="3.14" velocity="0.5"/>
    <origin rpy="0 0 0" xyz="0.02467 0.35571 0.01"/>
    <parent link="link_01"/>
		<child link="link_02"/>
	</joint>

	<joint name="link_02_tool" type="fixed">
    <origin rpy="0 0 0" xyz="0.02754 0.28 0.0"/>
    <parent link="link_02"/>
		<child link="tool"/>
	</joint>


</robot>
